Workbook

Sheet 0 - Home
B3: Overview
B4: This document aims to provide an outline of some key information captured regarding the project/application
B6: Project form
B7: Questionnaire to describe project contacts and stakeholdersand also to assess security and risk level of the project through defined metrics & indicators Please contact : GroupSecurity@sephora.fr if you have any question
B10: Disclaimer
B11: Please keep in mind that the following requierments should be taken into account before completing the document
B12: Identify what type data (see Confidentiality scale) is impacted, modified or created by the project | C12: Identify the personal data that will be collected, stored, transferred | D12: Involve your Local Data Privacy Contact if your project includes personal data | E12: Do not duplicate data in this project that already exists in other projects. | F12: Before any data is shared, work with Privacy/Legal team to put the relevant contract or, privacy clause or NDA are in place
B14: Tab | C14: Objectives
B15: 0 - Home | C15: The Guidelines sheet aims to present the different tabs of this sheet.
B16: 1 - General description | C16: The General description tab aims to present the general descriptive information about the IT project regardless of security of privacy aspects. More specificly, the sheet is devided in two sections : 1. General description The IT Project Manager has to provide descriptive information, such as the Project Title, the Business Domain, the objectives and the scope of the project etc. The Project Manager has to give information about the global architecture, the role of 3rd parties, the technological context (mobility, IoT, industrial systems...) and some use cases (number and type of users) in order to better assess the exposure of the project. 2. Main components The Project Manager has to list the different components (applications, systems and interfaces) that are part of the project. 3. Sub-contractors : The Project Manager has to list the different sub-contractors of the project by giving their name, explaining their role and listing the different documents integrated for assessment and agreement. 4. General questions The IT Project Manager must indicate all the use-cases corresponding the service provided to Sephora by writing "Yes" (instead of "No") on the appropriated lines.
B17: 2 - Qualification | C17: The Qualification tab aims to evaluate the security and privacy requirements and provides a first insight about exposure of this project. This includes global data mapping, evaluating the requirements of security and providing indicators about exposure. This sheet is divided in two different sections : 1. Data mapping : in this section, the Project Manager has to list the categories of data, and to specify if the project handles personal and/or strategic data. This enables to assess a sensitivity level especially for privacy. 2. Security requirements : The Project Manager has to define the requirements according to 6 criteria : Confidentiality, Integrity, Availability, Traceability, Privacy and Compliance from an business impact point of view.
B18: 3 - 3rd Security Party Policy | C18: The Applicability column (H) is automatically updated depending on the use-cases declared in "1 - General description" tab. It indicated the requirements to which an answer is necessary. For each requirement/line declared as applicable, you must fulfill the compliance level (column I): Not Compliant / Partial / Full. If a requirement is answered as non compliant or partially compliant: you must provide details about the reasons of the non compliance, about potential measures already implemented, or roadmap elements if projects are planned which may lead to a compliance. Those details can be provided in the J and K column. Warning: apart from columns I, J, K and L no other columns should be manually modified. This document becomes an appendix to the contract between the customer and the supplier.
B19: 4 - 3rd Party Assessment | C19: The 3rd Party Assessment tab aims to evaluate the organizational security of the partner as well as the technical security of the proposed solution. In this assessment, the partner is expected to support its answers with documents/policies/processes/certifications/audit results that will prove the security level of the solution and its organization.
B20: 5 - Risk Assessment | C20: The Risk assessment tab is the tool with which the IT Project Manager will make risk analysis and the DPIA if decided in the Data Privacy Focus (option) tab. One risks are assessed, countermeasures must be selected to reduce/avoid/transfer the risks (reduce impact or likelihood). It's an iterative approach. Measures must be added until residual risk is acceptable. This sheet is divided into two main parts : 1. Top risks (cyber and privacy) The IP Project Manager gives a list of top risks and associated threat scenarios, description and scoring of the potential impacts from a coporate point of view and from the subjects point of view (for PIA), assess likelihood and calculates risk score. 2. Security measures The Project Manager has to list all the countermeasures : those already implemented (transversal) and the specific measures to reduce the risks identified above.

Sheet 1 - General description
B2: GENERAL DESCRIPTION
B3: Project Title | C3: Livstick
B4: Objectives
B5: Main Functions
B6: Business Domain | C6: Digital | E6: Will the solution be used by mobile devices (smartphones, tablets…) ? | F6: No | H6: Business Sponsor | I6: Jérome OUGIER LABERGERE
B7: Department | C7: Figital | H7: Business Application Owner | I7: Margaux NOBRE
B8: Scope | C8: Local market | H8: IT Project Manager (Build & change)
B9: Operational points | C9: HQ | E9: Does the solution involve industrial systems ? | F9: No | H9: IT Application Manager (Run)
B10: Hosting | C10: External - Cloud SaaS | H10: Business Security Referent | I10: imane MILOUD
B11: Exposure | C11: Cloud / SaaS | H11: Security key contact | I11: Paul BLAISE
B12: Frequency | C12: Permanent | E12: Does the solution involve connected objects (IoT) ? | F12: No | H12: Local DPC (Data Privacy Contact)
B13: Integration with internal information system | C13: Yes | H13: Is the solution a POC ?
B14: API | C14: Yes | E14: Does the solution involve the usage or development of AI ? | F14: Yes | H14: Production start date
B16: =IF(C8="Global",4,IF(C8="Region",3,IF(C8="Local market",2,0))) -> 2 | C16: =IF(C10="Sephora - On premises",1,IF(C10="Sephora - Cloud",2,IF(C10="External - Cloud SaaS",3,IF(C10="External - Cloud IaaS/PaaS",4,IF(C10="External - Private SaaS",5,IF(C10="External - Private IaaS/PaaS",6,0)))))) -> 3 | D16: =IF(C11="Internet",4,IF(C11="Cloud / SaaS",3,IF(C11="Standalone",3,IF(C11="Intranet - On premises",2,0)))) -> 3
B17: Main components : applications, systems and interfaces
B18: Component name | C18: Type | D18: Editor | E18: Hosting | F18: Comment
B25: Sub-contractors
B26: Sub-contractor name | C26: Role | D26: Security & Data protection clauses | E26: 3rd party security policy | F26: Security Assurance Plan | G26: Reversibility Plan | H26: Hosting | I26: Comment
B33: GENERAL QUESTIONS TO BE FILLED BY ALL COMPANIES
B34: General questions about the service / Questions générales sur la prestation
B35: General questions / Questions générales | E35: To be filled by the Company / A remplir par la Société | G35: Client comments / Commentaires du Client
B36: Consultancy/audit services, survey in any business or support activity (ex: marketing, medias, sales, finance, HR, IT, logistics, general services, architecture, decoration,…) which need exchange means and temporary storage (data, documents) to ensure communication with the Customer? / Des prestations de type études/conseils/audits/enquêtes dans tout domaine d'activité métier ou support ? (ex: marketing, médias, vente , finance, RH, IT, logistique, services généraux, architecture, décoration…) nécessitant notamment des moyens d’échange et de stockage temporaires d'information (documents, données) pour assurer la communication avec le Client. | E36: No
B37: Provider's connection to the client's network for maintenance, support and/or operation on non-IT technical components? Examples: on-site maintenance of electrical installation, air conditionning, shop lighting, CCTV, intrusion detection, remote maintenance of electrical installation, physical access control system management / Des connexions du prestataire à des fins de maintenance, support et/ou d'exploitation, sur des composants techniques non IT, mais raccordés au réseau du client ? Exemples : maintenance sur site installation électrique, climatisation, éclairage boutique, vidéosurveillance, détection intrusion, maintenance à distance installation électrique, gestion système de contrôle d'accès physique | E37: No
B38: Operational/Support/Maintenance intervention on IT ressources of the Customer? Examples: administration of systems, networks or databaseslocal user support, TMA, managed services / Des interventions d'exploitation, de support ou de maintenance sur le Système d'Information du client ? Exemples : administration de systèmes, réseaux ou bases de données sur site, support de proximité aux utilisateurs, TMA, Infogérance | E38: No
B39: Is the service provided a call center activity? / Est-ce qu'un center d'appel est utilisé dans le cadre de la prestation ? | E39: No
B40: Hosting of Customer's Information System Platforms/Systems/Components? / L'hébergement de systèmes/plateformes/composants du SI du client? | E40: No
B41: Website hosting for the Customer? / L'hébergement d'un site Web pour le client ? | E41: No
B42: Provision of SaaS based softwares? / La fourniture de logiciels en mode SaaS ? | E42: Yes
B43: Realization of IT development? / La réalisation de développements informatiques ? | E43: Yes
B44: Provision of managed security services or infrastructures services . Examples: NOC/SOC, telephony, internet connectivity, video conference / La fourniture de services de sécurité managés ou opérateur de services d'infrastructures Exemple : NOC/SOC, téléphonie, connectivité internet, video-conférence | E44: No
B45: Is the service provided occasional or short-termed? / La prestation est-elle ponctuelle ou de courte durée ? | E45: No
B46: Is the service provided mainly performed on Customer' site? / La prestation se déroule principalement dans les locaux du client ? | E46: No
A51: Z | B51: PST LIGHT | G51: =IF(AND(E46="No",E45="No",E44="No",E42="No",E41="No",E40="No",E37="No",G60="No",G64="No",E36="Yes without production access",OR('2 - Qualification'!F61="Low",'2 - Qualification'!F61="Medium"),'2 - Qualification'!F63="Not Required",'2 - Qualification'!J63="Not required"),TRUE,FALSE) -> FALSE | H51: =IF(G51=TRUE, "Z", "X") -> X
A52: A | B52: Consultancy/audit services, survey in any business or support activity (ex: marketing, medias, sales, finance, HR, IT, logistics, general services, architecture, decoration,…) which need exchange means and temporary storage (data, documents) to ensure communication with the Customer? / Des prestations de type études/conseils/audits/enquêtes dans tout domaine d'activité métier ou support ? (ex: marketing, médias, vente , finance, RH, IT, logistique, services généraux, architecture, décoration…) nécessitant notamment des moyens d’échange et de stockage temporaires d'information (documents, données) pour assurer la communication avec le Client. | G52: =IF(E36="Yes with production access","Yes",IF(E36="Yes without production access","Yes",IF(E36="No","No",0))) -> No | H52: =IF(G52= "Yes", "A", "X") -> X
A53: B | B53: Provider's connection to the client's network for maintenance, support and/or operation on non-IT technical components? Examples: on-site maintenance of electrical installation, air conditionning, shop lighting, CCTV, intrusion detection, remote maintenance of electrical installation, physical access control system management / Des connexions du prestataire à des fins de maintenance, support et/ou d'exploitation, sur des composants techniques non IT, mais raccordés au réseau du client ? Exemples : maintenance sur site installation électrique, climatisation, éclairage boutique, vidéosurveillance, détection intrusion, maintenance à distance installation électrique, gestion système de contrôle d'accès physique | G53: =IF(E37= "Yes", "Yes", "No") -> No | H53: =IF(G53= "Yes", "B", "X") -> X
A54: C | B54: Operational/Support/Maintenance intervention on IT ressources of the Customer? Examples: administration of systems, networks or databaseslocal user support, TMA, managed services / Des interventions d'exploitation, de support ou de maintenance sur le Système d'Information du client ? Exemples : administration de systèmes, réseaux ou bases de données sur site, support de proximité aux utilisateurs, TMA, Infogérance | G54: =IF(E38= "Yes", "Yes", "No") -> No | H54: =IF(G54= "Yes", "C", "X") -> X
A55: D | B55: Hosting of Customer's Information System Platforms/Systems/Components? / L'hébergement de systèmes/plateformes/composants du SI du client? | G55: =IF(E40= "Yes", "Yes", "No") -> No | H55: =IF(G55= "Yes", "D", "X") -> X
A56: E | B56: Website hosting for the Customer? / L'hébergement d'un site Web pour le client ? | G56: =IF(E41= "Yes", "Yes", "No") -> No | H56: =IF(G56= "Yes", "E", "X") -> X
A57: F | B57: Provision of SaaS based softwares? / La fourniture de logiciels en mode SaaS ? | G57: =IF(E42= "Yes", "Yes", "No") -> Yes | H57: =IF(G57= "Yes", "F", "X") -> F
A58: G | B58: Realization of IT development? / La réalisation de développements informatiques ? | G58: =IF(E43= "Yes", "Yes", "No") -> Yes | H58: =IF(G58= "Yes", "G", "X") -> G
...

Sheet 2 - Qualification
B2: 1 - GENERAL DATA MAPPING
B3: Information management | G3: Application access management
B4: Type of information | C4: Yes/No | D4: WHERE the data will be stored ? | E4: Number of records | F4: WHO will access the information ? | G4: Profil name | H4: WHO will use the application ? | I4: Individual account ? | J4: Number of end users | K4: Description of profile rights and features
B5: Financial / Accounting | C5: Yes
B6: Legal
B7: Security (logs, configuration, etc)
B8: Commercial | C8: Yes
B9: Partner Information (B2B)
B10: Partner employee
B11: Employees Information | C11: Yes
B12: End Customer information (B2C) | C12: Yes
B13: Public data
B14: Other (give comments) | D14: Comments :
B15: Personal data
B16: Personal data : Type of information | E16: Yes/No | F16: Comments
B17: Civil status, identity, identification data | E17: Yes
B18: Physical appearance
B19: ID credentials (ID card number, passport, residence permit)
B20: Personal life (living habits, marital status, etc.)
B21: Professional life (résumé, education and professional training, awards, etc.)
B22: Economic and financial information (income, financial situation, tax situation, etc.)
B23: Connection data (IP addresses, event logs, etc.)
B24: Location data (travels, GPS data, GSM data, etc.)
B25: Social security number
B26: Biometric data
B27: Bank data (Credit card numbers)
B28: Philosophical, political, religious and trade-union views, sex life, health data, racial or ethnic origin, data concerning health or sex life
B29: Offenses, convictions, security measures
B30: Other sensitive personal data
B31: Data Retention Period | F31: 3rd Party: Sephora Legal - Contract:
B33: 2 - SECURITY ATTRIBUTES
B34: C (Confidentiality) | C34: I (Integrity) | E34: A (Availability) | G34: T (Traceability) | I34: P (Privacy) | K34: C (Compliance)
B35: 3 | C35: 3 | E35: 3 | G35: 2 | I35: 2 | K35: =IF(ISBLANK(I35),"Please complete the Privacy attribute",IF(I35=4,5,IF(I35=3,4,IF(I35=2,3,IF(I35=0,1,"Please check with gouvernance security teams to assess this attribute"))))) -> 3
B37: 3 - IMPACT ANALYSIS | N37: C (Confidentiality)
B38: Topics | E38: Options | F38: Comments | N38: 4 - Strictly Confidential | O38: Information is restricted above Confidential level, to a designated, named group of individuals on a strictly need to know basis. This also includes categories such as Privileged data and sensitive personal data ( health, salary, political affiliation, etc.) where Legal teams must be consulted.
B39: What would be the impact of data disclosure? | D39: To employees | N39: 3- Confidential | O39: Information is only available to a specific group of employees with a need to know – e.g. standard contracts or customer information. This also includes non-sensitive personal data.
D40: To a competitor | N40: 2- Internal | O40: Information is only available to INTERNAL’s employees & authorized external workers - e.g. training tools, policy, standards.
D41: To a supplier / sub-contractor | E41: 1 - Low | N41: 1- Public | O41: Public: information is available to the public - e.g. advertising, press releases.
D42: To the general public / Medias | N42: I (Integrity)
B43: What would be the impact if data integrity is affected ? | D43: Data is definitely lost | N43: 4- Enhanced | O43: No unauthorized modification tolerated
...

Sheet 3 - 3rd Party Security Policy
B1: 3 - THIRD PARTY SECURITY POLICY
B2: Chapter / Chapitre | C2: N° | D2: Title / Titre | E2: Description of the requirement / Description de l'exigence | F2: Use cases (*) / Cas d'usage (*) | G2: Applicability / Applicabilité | H2: Compliance / Conformité | I2: Detailed implemented measures / Détails sur les mesures implémentées | J2: Optional comment on non compliant or partially compliant controls / Commentaire éventuel sur les mesures non ou partiellement conformes
A3: 1 | B3: Framework for the contractual relationship / Cadrage de la relation contractuelle | C3: 1.1 | D3: Service provider’s Security Policy / Politique de Sécurité de la Société | E3: The service provider shall make its "Information System Security Policy" available to the client. / Le prestataire tient à la disposition du client sa « Politique de sécurité du système d'information ». | F3: B,C,D,E,F,G,H | G3: =IF(AND('1 - General description'!$G$51=FALSE, K3= TRUE),"Applicable","N.A") -> Applicable | K3: =OR(ISNUMBER(FIND('1 - General description'!$H$51,F3)),ISNUMBER(FIND('1 - General description'!$H$52,F3)),ISNUMBER(FIND('1 - General description'!$H$53,F3)),ISNUMBER(FIND('1 - General description'!$H$54,F3)),ISNUMBER(FIND('1 - General description'!$H$55,F3)),ISNUMBER(FIND('1 - General description'!$H$56,F3)),ISNUMBER(FIND('1 - General description'!$H$57,F3)),ISNUMBER(FIND('1 - General description'!$H$58,F3)),ISNUMBER(FIND('1 - General description'!$H$59,F3)),ISNUMBER(FIND('1 - General description'!$H$60,F3)),ISNUMBER(FIND('1 - General description'!$H$61,F3)),ISNUMBER(FIND('1 - General description'!$H$62,F3)),ISNUMBER(FIND('1 - General description'!$H$63,F3)),ISNUMBER(FIND('1 - General description'!$H$64,F3))) -> TRUE
A4: 1 | B4: Framework for the contractual relationship / Cadrage de la relation contractuelle | C4: 1.2 | D4: Certifications | E4: If the service provider claims to have security certifications, it will make it available to the client, specifying their scope, the expiry date, the identity of the certifying body, the date of the last audit and the conclusions of that audit. / Si le prestataire dispose de certifications en matière de sécurité et souhaite s'en prévaloir, il tiendra à la disposition du client ces certifications en précisant leur périmètre, la date d’expiration, l’identité de l’organisme certificateur, la date du dernier audit et les conclusions de cet audit. | F4: C,D,E,F,H | G4: =IF(AND('1 - General description'!$G$51=FALSE, K4= TRUE),"Applicable","N.A") -> Applicable | K4: =OR(ISNUMBER(FIND('1 - General description'!$H$51,F4)),ISNUMBER(FIND('1 - General description'!$H$52,F4)),ISNUMBER(FIND('1 - General description'!$H$53,F4)),ISNUMBER(FIND('1 - General description'!$H$54,F4)),ISNUMBER(FIND('1 - General description'!$H$55,F4)),ISNUMBER(FIND('1 - General description'!$H$56,F4)),ISNUMBER(FIND('1 - General description'!$H$57,F4)),ISNUMBER(FIND('1 - General description'!$H$58,F4)),ISNUMBER(FIND('1 - General description'!$H$59,F4)),ISNUMBER(FIND('1 - General description'!$H$60,F4)),ISNUMBER(FIND('1 - General description'!$H$61,F4)),ISNUMBER(FIND('1 - General description'!$H$62,F4)),ISNUMBER(FIND('1 - General description'!$H$63,F4)),ISNUMBER(FIND('1 - General description'!$H$64,F4))) -> TRUE
A5: 1 | B5: Framework for the contractual relationship / Cadrage de la relation contractuelle | C5: 1.3 | D5: Security Assurance Plan / Plan d'Assurance Sécurité | E5: The service provider shall submit a Security Assurance Plan (SAP) to the client which describes all of the security processes and solutions it will use to comply with the security requirements of the service provision. The SAP must be approved by the client and appended to the contract or order prior to the start of the contract. The Security Assurance Plan is a document subject to change over the life of the contract. The service provider shall submit any proposed changes for approval by the client. Such revisions of the SAP may be approved, for example, at the steering committees planned during the service delivery. The service provider undertakes to fulfil its security obligations in accordance with the Security Assurance Plan. The terms and conditions laid down by the SAP shall prevail over the service provider’s security documents. / Le prestataire soumet au client un Plan d’Assurance Sécurité (PAS) qui décrit l’ensemble des processus et dispositifs sécurité qu’elle met en œuvre pour respecter les exigences de sécurité de la prestation. Le PAS doit être approuvé par le client et annexé au contrat ou à la commande, préalablement au démarrage de la prestation. Le PAS est un document susceptible d'évoluer au cours de la prestation. Le prestataire soumet des propositions d’évolutions qui doivent être validées par le client. Ces révisions du PAS peuvent être validées par exemple à l’occasion des Comités prévus pour le pilotage de la prestation. Le prestataire s’engage à exécuter ses obligations vis-à-vis de la sécurité selon le PAS. Les conditions du PAS sont prioritaires par rapport aux documents de sécurité du prestataire. | F5: B, D, E, F, H | G5: =IF(AND('1 - General description'!$G$51=FALSE, K5= TRUE),"Applicable","N.A") -> Applicable | K5: =OR(ISNUMBER(FIND('1 - General description'!$H$51,F5)),ISNUMBER(FIND('1 - General description'!$H$52,F5)),ISNUMBER(FIND('1 - General description'!$H$53,F5)),ISNUMBER(FIND('1 - General description'!$H$54,F5)),ISNUMBER(FIND('1 - General description'!$H$55,F5)),ISNUMBER(FIND('1 - General description'!$H$56,F5)),ISNUMBER(FIND('1 - General description'!$H$57,F5)),ISNUMBER(FIND('1 - General description'!$H$58,F5)),ISNUMBER(FIND('1 - General description'!$H$59,F5)),ISNUMBER(FIND('1 - General description'!$H$60,F5)),ISNUMBER(FIND('1 - General description'!$H$61,F5)),ISNUMBER(FIND('1 - General description'!$H$62,F5)),ISNUMBER(FIND('1 - General description'!$H$63,F5)),ISNUMBER(FIND('1 - General description'!$H$64,F5))) -> TRUE
A6: 1 | B6: Framework for the contractual relationship / Cadrage de la relation contractuelle | C6: 1.4 | D6: Legal reminder : Duty to advise / Rappel légal : Devoir de Conseil | E6: The service provider shall be bound by a duty to advise and a duty to warn regarding security. In particular, whenever an operation is planned, it undertakes to notify the client of the security risks for data or for the IS and shall suggest measures to deal with such risks. This duty to advise shall be based on sound knowledge of the state of the art. External link : https://www.transatlantic-lawyer.com/the-obligation-of-information-and-the-duty-to-advise-in-contracts-under-french-law/ / Le prestataire est tenu à une obligation de conseil et de mise en garde en matière de sécurité. En particulier, lorsqu'une opération est envisagée, il s’engage à informer le client sur les risques vis-à-vis de la sécurité des données ou du SI et propose des actions pour traiter ces risques. Ce devoir de conseil s’appuie sur une bonne connaissance de l’état de l’art. Lien externe : https://www.droit-technologie.org/actualites/lobligation-dinformation-du-prestataire-informatique-a-legard-de-son-client/ | F6: B, C, D, E, F, H | G6: =IF(AND('1 - General description'!$G$51=FALSE, K6= TRUE),"Applicable","N.A") -> Applicable | K6: =OR(ISNUMBER(FIND('1 - General description'!$H$51,F6)),ISNUMBER(FIND('1 - General description'!$H$52,F6)),ISNUMBER(FIND('1 - General description'!$H$53,F6)),ISNUMBER(FIND('1 - General description'!$H$54,F6)),ISNUMBER(FIND('1 - General description'!$H$55,F6)),ISNUMBER(FIND('1 - General description'!$H$56,F6)),ISNUMBER(FIND('1 - General description'!$H$57,F6)),ISNUMBER(FIND('1 - General description'!$H$58,F6)),ISNUMBER(FIND('1 - General description'!$H$59,F6)),ISNUMBER(FIND('1 - General description'!$H$60,F6)),ISNUMBER(FIND('1 - General description'!$H$61,F6)),ISNUMBER(FIND('1 - General description'!$H$62,F6)),ISNUMBER(FIND('1 - General description'!$H$63,F6)),ISNUMBER(FIND('1 - General description'!$H$64,F6))) -> TRUE
A7: 2 | B7: Security related to Human Resources / Sécurité liée aux Ressources Humaines | C7: 2.1 | D7: Organisation | E7: The service provider appoints one or several privileged points of contacts on the security topics in the comment cell. Responsibility of this/these persons should covers: - Implementation of the security policy and processes - Protection against unauthorised access, data disclosure and the modification or destruction of content or systems - Reporting of potential or known security risks or incidents - Management of security incidents Any specific demand from the customer regarding security must be deatl with diligence and with according priority level by the service provider. / Le prestataire désigne un ou des points de contact privilégiés sur les aspects sécurité dans la case commentaire. Les responsabilités de cette ou ces personne(s) portent notamment sur : - La mise en œuvre de sa politique et de ses processus de sécurité ; - La protection contre des accès non autorisés, la divulgation de données, la modification ou la destruction de contenus ou de systèmes ; - La notification de failles présumées ou avérées de sécurité ; - La prise en charge des incidents de sécurité. Toute demande spécifique du client relative à la sécurité doit être traitée avec diligence et de manière prioritaire par le prestataire. | F7: B, C, D, E, F, H | G7: =IF(AND('1 - General description'!$G$51=FALSE, K7= TRUE),"Applicable","N.A") -> Applicable | K7: =OR(ISNUMBER(FIND('1 - General description'!$H$51,F7)),ISNUMBER(FIND('1 - General description'!$H$52,F7)),ISNUMBER(FIND('1 - General description'!$H$53,F7)),ISNUMBER(FIND('1 - General description'!$H$54,F7)),ISNUMBER(FIND('1 - General description'!$H$55,F7)),ISNUMBER(FIND('1 - General description'!$H$56,F7)),ISNUMBER(FIND('1 - General description'!$H$57,F7)),ISNUMBER(FIND('1 - General description'!$H$58,F7)),ISNUMBER(FIND('1 - General description'!$H$59,F7)),ISNUMBER(FIND('1 - General description'!$H$60,F7)),ISNUMBER(FIND('1 - General description'!$H$61,F7)),ISNUMBER(FIND('1 - General description'!$H$62,F7)),ISNUMBER(FIND('1 - General description'!$H$63,F7)),ISNUMBER(FIND('1 - General description'!$H$64,F7))) -> TRUE
A8: 2 | B8: Security related to Human Resources / Sécurité liée aux Ressources Humaines | C8: 2.2 | D8: Training / Formation | E8: The service provider shall ensure that its staff responsible for the service delivery receive training on the relevant tools and security processes. It shall also provide the client with a description of its training programme. / Le prestataire veille à ce que son personnel chargé de la prestation de services reçoive une formation sur les outils et les processus de sécurité. Il fournira également au client une description de son programme de formation. | F8: B, C, D, E, F, H | G8: =IF(AND('1 - General description'!$G$51=FALSE, K8= TRUE),"Applicable","N.A") -> Applicable | K8: =OR(ISNUMBER(FIND('1 - General description'!$H$51,F8)),ISNUMBER(FIND('1 - General description'!$H$52,F8)),ISNUMBER(FIND('1 - General description'!$H$53,F8)),ISNUMBER(FIND('1 - General description'!$H$54,F8)),ISNUMBER(FIND('1 - General description'!$H$55,F8)),ISNUMBER(FIND('1 - General description'!$H$56,F8)),ISNUMBER(FIND('1 - General description'!$H$57,F8)),ISNUMBER(FIND('1 - General description'!$H$58,F8)),ISNUMBER(FIND('1 - General description'!$H$59,F8)),ISNUMBER(FIND('1 - General description'!$H$60,F8)),ISNUMBER(FIND('1 - General description'!$H$61,F8)),ISNUMBER(FIND('1 - General description'!$H$62,F8)),ISNUMBER(FIND('1 - General description'!$H$63,F8)),ISNUMBER(FIND('1 - General description'!$H$64,F8))) -> TRUE
A9: 2 | B9: Security related to Human Resources / Sécurité liée aux Ressources Humaines | C9: 2.3 | D9: Awareness / Sensibilisation | E9: The service provider shall ensure that both its own staff and the staff of its subcontractors are fully informed and aware of the security requirements laid down by the contract. / Le prestataire veille à ce que son personnel et ceux de ses sous-traitants soient pleinement informés des exigences de sécurité contractuelles et soumis contractuellement à ces mêmes exigences. | F9: A, B, C, D, E, F, G, H, I, J, K, L, M, Z | G9: =IF(K9= TRUE,"Applicable","N.A") -> Applicable | K9: =OR(ISNUMBER(FIND('1 - General description'!$H$51,F9)),ISNUMBER(FIND('1 - General description'!$H$52,F9)),ISNUMBER(FIND('1 - General description'!$H$53,F9)),ISNUMBER(FIND('1 - General description'!$H$54,F9)),ISNUMBER(FIND('1 - General description'!$H$55,F9)),ISNUMBER(FIND('1 - General description'!$H$56,F9)),ISNUMBER(FIND('1 - General description'!$H$57,F9)),ISNUMBER(FIND('1 - General description'!$H$58,F9)),ISNUMBER(FIND('1 - General description'!$H$59,F9)),ISNUMBER(FIND('1 - General description'!$H$60,F9)),ISNUMBER(FIND('1 - General description'!$H$61,F9)),ISNUMBER(FIND('1 - General description'!$H$62,F9)),ISNUMBER(FIND('1 - General description'!$H$63,F9)),ISNUMBER(FIND('1 - General description'!$H$64,F9))) -> TRUE
A10: 2 | B10: Security related to Human Resources / Sécurité liée aux Ressources Humaines | C10: 2.4 | D10: Staff commitment / Engagement du personnel | E10: The service provider shall ensure that each member of its staff individually undertakes to keep the confidentiality of all types of sensitive information of which they may become aware when delivering the service. / Le prestataire garantit que ses personnels s’engagent individuellement à respecter la confidentialité de tout type d’information confidentielle qu’ils sont susceptibles de connaître dans le cadre de la prestation. | F10: Z | G10: =IF(K10= TRUE,"Applicable","N.A") -> N.A | K10: =OR(ISNUMBER(FIND('1 - General description'!$H$51,F10)),ISNUMBER(FIND('1 - General description'!$H$52,F10)),ISNUMBER(FIND('1 - General description'!$H$53,F10)),ISNUMBER(FIND('1 - General description'!$H$54,F10)),ISNUMBER(FIND('1 - General description'!$H$55,F10)),ISNUMBER(FIND('1 - General description'!$H$56,F10)),ISNUMBER(FIND('1 - General description'!$H$57,F10)),ISNUMBER(FIND('1 - General description'!$H$58,F10)),ISNUMBER(FIND('1 - General description'!$H$59,F10)),ISNUMBER(FIND('1 - General description'!$H$60,F10)),ISNUMBER(FIND('1 - General description'!$H$61,F10)),ISNUMBER(FIND('1 - General description'!$H$62,F10)),ISNUMBER(FIND('1 - General description'!$H$63,F10)),ISNUMBER(FIND('1 - General description'!$H$64,F10))) -> FALSE
A11: 2 | B11: Security related to Human Resources / Sécurité liée aux Ressources Humaines | C11: 2.4 | D11: Security Charter / Charte sécurité | E11: The service provider’s staff or the staff of its subcontractors carrying out work on the client’s premises shall comply with the client’s Security Charter during the period or their missions. / Les personnels du prestataire ou de ses sous-traitants intervenant dans les locaux du client se conforment à la charte sécurité du système d'information du client dans le cadre de l’exercice de leur mission. | F11: L | G11: =IF(AND('1 - General description'!$G$51=FALSE, K11= TRUE),"Applicable","N.A") -> N.A | K11: =OR(ISNUMBER(FIND('1 - General description'!$H$51,F11)),ISNUMBER(FIND('1 - General description'!$H$52,F11)),ISNUMBER(FIND('1 - General description'!$H$53,F11)),ISNUMBER(FIND('1 - General description'!$H$54,F11)),ISNUMBER(FIND('1 - General description'!$H$55,F11)),ISNUMBER(FIND('1 - General description'!$H$56,F11)),ISNUMBER(FIND('1 - General description'!$H$57,F11)),ISNUMBER(FIND('1 - General description'!$H$58,F11)),ISNUMBER(FIND('1 - General description'!$H$59,F11)),ISNUMBER(FIND('1 - General description'!$H$60,F11)),ISNUMBER(FIND('1 - General description'!$H$61,F11)),ISNUMBER(FIND('1 - General description'!$H$62,F11)),ISNUMBER(FIND('1 - General description'!$H$63,F11)),ISNUMBER(FIND('1 - General description'!$H$64,F11))) -> FALSE
A12: 2 | B12: Security related to Human Resources / Sécurité liée aux Ressources Humaines | C12: 2.5 | D12: Hosting agreement / Convention d'accueil | E12: If members of the staff of the service provider have to work on the client’s premises for a long period, a tripartite hosting agreement must be signed between the client, the service provider and each o these members. / En cas de mission de longue durée dans les locaux du client, une convention d’accueil tripartite doit être signée entre le client, le prestataire et chaque membre du personnel du prestataire intervenant sur le site du client. | F12: L | G12: =IF(AND('1 - General description'!$G$51=FALSE, K12= TRUE),"Applicable","N.A") -> N.A | K12: =OR(ISNUMBER(FIND('1 - General description'!$H$51,F12)),ISNUMBER(FIND('1 - General description'!$H$52,F12)),ISNUMBER(FIND('1 - General description'!$H$53,F12)),ISNUMBER(FIND('1 - General description'!$H$54,F12)),ISNUMBER(FIND('1 - General description'!$H$55,F12)),ISNUMBER(FIND('1 - General description'!$H$56,F12)),ISNUMBER(FIND('1 - General description'!$H$57,F12)),ISNUMBER(FIND('1 - General description'!$H$58,F12)),ISNUMBER(FIND('1 - General description'!$H$59,F12)),ISNUMBER(FIND('1 - General description'!$H$60,F12)),ISNUMBER(FIND('1 - General description'!$H$61,F12)),ISNUMBER(FIND('1 - General description'!$H$62,F12)),ISNUMBER(FIND('1 - General description'!$H$63,F12)),ISNUMBER(FIND('1 - General description'!$H$64,F12))) -> FALSE
A13: 2 | B13: Security related to Human Resources / Sécurité liée aux Ressources Humaines | C13: 2.6 | D13: Charter for Administrators / Charte administrateurs | E13: If members of the service provider’s staff has to use privileged accounts to access to the client’s information system, those members must sign the charter dedicated to administrators and privileged users. This charter is provided by the client. / Si les comptes informatiques utilisés par les personnels du prestataire pour accéder au système d'information du client sont des comptes à privilèges, alors ces personnels doivent signer la charte dédiée aux administrateurs et détenteurs de comptes à privilèges, communiquée par le client au prestataire. | F13: B, C, D, E, F, H, M | G13: =IF(K13= TRUE,"Applicable","N.A") -> Applicable | K13: =OR(ISNUMBER(FIND('1 - General description'!$H$51,F13)),ISNUMBER(FIND('1 - General description'!$H$52,F13)),ISNUMBER(FIND('1 - General description'!$H$53,F13)),ISNUMBER(FIND('1 - General description'!$H$54,F13)),ISNUMBER(FIND('1 - General description'!$H$55,F13)),ISNUMBER(FIND('1 - General description'!$H$56,F13)),ISNUMBER(FIND('1 - General description'!$H$57,F13)),ISNUMBER(FIND('1 - General description'!$H$58,F13)),ISNUMBER(FIND('1 - General description'!$H$59,F13)),ISNUMBER(FIND('1 - General description'!$H$60,F13)),ISNUMBER(FIND('1 - General description'!$H$61,F13)),ISNUMBER(FIND('1 - General description'!$H$62,F13)),ISNUMBER(FIND('1 - General description'!$H$63,F13)),ISNUMBER(FIND('1 - General description'!$H$64,F13))) -> TRUE
A14: 2 | B14: Security related to Human Resources / Sécurité liée aux Ressources Humaines | C14: 2.7 | D14: Display of service provider status / Affichage du statut de prestataire | E14: The service provider’s staff shall not introduce themselves as staff of the client when delivering the service, both at meetings, on their CV or on social media, for example. / Les personnels du prestataire ne doivent pas se présenter comme des personnels du client dans le cadre de leur mission pour le client, que ce soit lors de réunions, sur leur CV ou sur les réseaux sociaux, par exemple. | F14: L | G14: =IF(AND('1 - General description'!$G$51=FALSE, K14= TRUE),"Applicable","N.A") -> N.A | K14: =OR(ISNUMBER(FIND('1 - General description'!$H$51,F14)),ISNUMBER(FIND('1 - General description'!$H$52,F14)),ISNUMBER(FIND('1 - General description'!$H$53,F14)),ISNUMBER(FIND('1 - General description'!$H$54,F14)),ISNUMBER(FIND('1 - General description'!$H$55,F14)),ISNUMBER(FIND('1 - General description'!$H$56,F14)),ISNUMBER(FIND('1 - General description'!$H$57,F14)),ISNUMBER(FIND('1 - General description'!$H$58,F14)),ISNUMBER(FIND('1 - General description'!$H$59,F14)),ISNUMBER(FIND('1 - General description'!$H$60,F14)),ISNUMBER(FIND('1 - General description'!$H$61,F14)),ISNUMBER(FIND('1 - General description'!$H$62,F14)),ISNUMBER(FIND('1 - General description'!$H$63,F14)),ISNUMBER(FIND('1 - General description'!$H$64,F14))) -> FALSE
A15: 2 | B15: Security related to Human Resources / Sécurité liée aux Ressources Humaines | C15: 2.8 | D15: Subcontracting / Sous-traitance | E15: The service provider shall not use any subcontractors without the explicit consent of the client. The client reserves the right to reject a subcontractor if it does not meet the client’s security requirements. The use of a subcontractor must not reduce the level of security governed by the scope of the contract entered into with the client. In all cases, the service provider shall accept sole liability to the client for any breaches of security within that scope and undertakes to subject any subcontractors to obligations similar to those laid down in the contract, wherever these are applicable. / Le prestataire ne peut recourir à un sous-traitant sans l’accord écrit et préalable du client. Le client se réserve la possibilité de refuser un sous-traitant si celui-ci ne répond pas aux exigences de sécurité du client. Le recours à ce sous-traitant ne doit pas être de nature à réduire le niveau de sécurité du périmètre objet du contrat avec le client. Dans tous les cas, le prestataire reste seul responsable vis-à-vis du client des atteintes à la sécurité sur ce périmètre et s'engage à soumettre ses éventuels sous-traitants à des obligations similaires à celles contenues dans le contrat, sous réserve de leur applicabilité (notamment les obligations relatives à la sécurité, la confidentialité, la protection des données, l'audit et l'assurance). | F15: A, B, C, D, E, F, G, H, I, J, K, L, M | G15: =IF(AND('1 - General description'!$G$51=FALSE, K15= TRUE),"Applicable","N.A") -> Applicable | K15: =OR(ISNUMBER(FIND('1 - General description'!$H$51,F15)),ISNUMBER(FIND('1 - General description'!$H$52,F15)),ISNUMBER(FIND('1 - General description'!$H$53,F15)),ISNUMBER(FIND('1 - General description'!$H$54,F15)),ISNUMBER(FIND('1 - General description'!$H$55,F15)),ISNUMBER(FIND('1 - General description'!$H$56,F15)),ISNUMBER(FIND('1 - General description'!$H$57,F15)),ISNUMBER(FIND('1 - General description'!$H$58,F15)),ISNUMBER(FIND('1 - General description'!$H$59,F15)),ISNUMBER(FIND('1 - General description'!$H$60,F15)),ISNUMBER(FIND('1 - General description'!$H$61,F15)),ISNUMBER(FIND('1 - General description'!$H$62,F15)),ISNUMBER(FIND('1 - General description'!$H$63,F15)),ISNUMBER(FIND('1 - General description'!$H$64,F15))) -> TRUE
A16: 3 | B16: Confidentiality / Confidentialité | C16: 3.1 | D16: Autorisations | E16: The access rights of the service provider’s staff to the platforms it makes available to the client must be clearly defined, communicated to and approved by the client. The same shall apply to all access to the programs and content that the client installs, produces and uses on those platforms. / Les droits d’accès des personnels du prestataire aux plates-formes qu’elle met à disposition du client doivent être précisément définis, communiqués au client et validés par celui-ci. Il en est de même pour les accès éventuels aux programmes et aux contenus que le client va installer, produire et exploiter sur ces plates-formes. | F16: B, C, D, E, F, H | G16: =IF(AND('1 - General description'!$G$51=FALSE, K16= TRUE),"Applicable","N.A") -> Applicable | K16: =OR(ISNUMBER(FIND('1 - General description'!$H$51,F16)),ISNUMBER(FIND('1 - General description'!$H$52,F16)),ISNUMBER(FIND('1 - General description'!$H$53,F16)),ISNUMBER(FIND('1 - General description'!$H$54,F16)),ISNUMBER(FIND('1 - General description'!$H$55,F16)),ISNUMBER(FIND('1 - General description'!$H$56,F16)),ISNUMBER(FIND('1 - General description'!$H$57,F16)),ISNUMBER(FIND('1 - General description'!$H$58,F16)),ISNUMBER(FIND('1 - General description'!$H$59,F16)),ISNUMBER(FIND('1 - General description'!$H$60,F16)),ISNUMBER(FIND('1 - General description'!$H$61,F16)),ISNUMBER(FIND('1 - General description'!$H$62,F16)),ISNUMBER(FIND('1 - General description'!$H$63,F16)),ISNUMBER(FIND('1 - General description'!$H$64,F16))) -> TRUE
A17: 3 | B17: Confidentiality / Confidentialité | C17: 3.2 | D17: Confidentiality agreement / Engagement de confidentialité | E17: The service provider shall take all necessary measures to ensure that none of the client’s content is disclosed to any unauthorised individual or legal entity. This obligation applies to all content, irrespective of the medium or nature, handled or exchanged when delivering the service. The confidentiality obligation also concerns all information of which disclosure is deemed to be a threat to the security of the system (passwords, data encryption keys and documentation regarding system architecture and security, etc.). / Le prestataire s’engage à mettre tout en œuvre pour que les contenus du client ne soient pas divulgués à des personnes physiques ou morales non autorisées. Cet engagement concerne tous les contenus quel qu’en soit le support ou la nature, manipulés ou échangés dans le cadre de la prestation. L’engagement de confidentialité concerne aussi toute information dont la divulgation est de nature à porter atteinte à la sécurité du système (mots de passe, clés de chiffrement, documentations relative à l’architecture et la sécurité du système, etc.). | F17: A, B, C, D, E, F, G, H, I, J, K, L, M, Z | G17: =IF(K17= TRUE,"Applicable","N.A") -> Applicable | K17: =OR(ISNUMBER(FIND('1 - General description'!$H$51,F17)),ISNUMBER(FIND('1 - General description'!$H$52,F17)),ISNUMBER(FIND('1 - General description'!$H$53,F17)),ISNUMBER(FIND('1 - General description'!$H$54,F17)),ISNUMBER(FIND('1 - General description'!$H$55,F17)),ISNUMBER(FIND('1 - General description'!$H$56,F17)),ISNUMBER(FIND('1 - General description'!$H$57,F17)),ISNUMBER(FIND('1 - General description'!$H$58,F17)),ISNUMBER(FIND('1 - General description'!$H$59,F17)),ISNUMBER(FIND('1 - General description'!$H$60,F17)),ISNUMBER(FIND('1 - General description'!$H$61,F17)),ISNUMBER(FIND('1 - General description'!$H$62,F17)),ISNUMBER(FIND('1 - General description'!$H$63,F17)),ISNUMBER(FIND('1 - General description'!$H$64,F17))) -> TRUE
A18: 3 | B18: Confidentiality / Confidentialité | C18: 3.3 | D18: Disclosure to third parties / Communication à un tiers | E18: The service provider is not authorised to transfer any data or information about the contract, or obtained in connection with the delivery of the contract, to any third parties without the prior explicit consent of the client. / Le prestataire n’est pas autorisé à transférer des données ou des informations relatives au contrat ou obtenues dans le cadre de l’exercice du contrat à un tiers sans une autorisation préalable explicite du client. | F18: Z | G18: =IF(K18= TRUE,"Applicable","N.A") -> N.A | K18: =OR(ISNUMBER(FIND('1 - General description'!$H$51,F18)),ISNUMBER(FIND('1 - General description'!$H$52,F18)),ISNUMBER(FIND('1 - General description'!$H$53,F18)),ISNUMBER(FIND('1 - General description'!$H$54,F18)),ISNUMBER(FIND('1 - General description'!$H$55,F18)),ISNUMBER(FIND('1 - General description'!$H$56,F18)),ISNUMBER(FIND('1 - General description'!$H$57,F18)),ISNUMBER(FIND('1 - General description'!$H$58,F18)),ISNUMBER(FIND('1 - General description'!$H$59,F18)),ISNUMBER(FIND('1 - General description'!$H$60,F18)),ISNUMBER(FIND('1 - General description'!$H$61,F18)),ISNUMBER(FIND('1 - General description'!$H$62,F18)),ISNUMBER(FIND('1 - General description'!$H$63,F18)),ISNUMBER(FIND('1 - General description'!$H$64,F18))) -> FALSE
A19: 4 | B19: Identity and access management / Gestion des identités et des accès | C19: 4.1 | D19: Remote access to the client's information system / Accès distant au système d'information du Client | E19: In cases where remote operations are carried out by the service provider on the client’s resources , the service provider will always use nominative accounts allocated by the client. These accounts will be created on demand by the service provider. It must provide a list of the members of staff concerned and notify the client whenever a member of staff leaves, or whenever a new member of staff is allocated to the service. These accounts are strictly limited to a personal use and the service provider is responsaible of ensuring that these accounts will not be shared among its staff. / Dans le cas d’opérations réalisées à distance par le prestataire sur les systèmes d'information du client, le prestataire n'utilisera que des comptes nominatifs. Ces comptes pourront être créé sur demande du prestataire. Il devra fournir la liste des personnels concernés et informer le client dès qu’un personnel quitte la prestation ou le prestataire, ou dès qu’un nouveau personnel est affecté à la prestation. Ces comptes sont à usage strictement personnel et le prestataire est responsable de s'assurer que ces comptes ne seront pas partagés entre ses personnels. | F19: A, C, I, J, M | G19: =IF(AND('1 - General description'!$G$51=FALSE, K19= TRUE),"Applicable","N.A") -> Applicable | K19: =OR(ISNUMBER(FIND('1 - General description'!$H$51,F19)),ISNUMBER(FIND('1 - General description'!$H$52,F19)),ISNUMBER(FIND('1 - General description'!$H$53,F19)),ISNUMBER(FIND('1 - General description'!$H$54,F19)),ISNUMBER(FIND('1 - General description'!$H$55,F19)),ISNUMBER(FIND('1 - General description'!$H$56,F19)),ISNUMBER(FIND('1 - General description'!$H$57,F19)),ISNUMBER(FIND('1 - General description'!$H$58,F19)),ISNUMBER(FIND('1 - General description'!$H$59,F19)),ISNUMBER(FIND('1 - General description'!$H$60,F19)),ISNUMBER(FIND('1 - General description'!$H$61,F19)),ISNUMBER(FIND('1 - General description'!$H$62,F19)),ISNUMBER(FIND('1 - General description'!$H$63,F19)),ISNUMBER(FIND('1 - General description'!$H$64,F19))) -> TRUE
A20: 4 | B20: Identity and access management / Gestion des identités et des accès | C20: 4.2 | D20: Revocation of accounts / Déprovisionnement des comptes | E20: The service provider shall ensure that anyone who is no longer part of its staff ceases to hold active accounts which might be used to access the client’s resources or the platforms made available to the client. / Le prestataire veille à ce que les personnes qui ne font plus partie de son personnel ne possèdent plus, au moment de leur départ de la société, de comptes actifs susceptibles d’être utilisés pour un accès au système d'information du client ou à des plates-formes mises à disposition du client. | F20: B, C, D, E, F, H, Z | G20: =IF(K20= TRUE,"Applicable","N.A") -> Applicable | K20: =OR(ISNUMBER(FIND('1 - General description'!$H$51,F20)),ISNUMBER(FIND('1 - General description'!$H$52,F20)),ISNUMBER(FIND('1 - General description'!$H$53,F20)),ISNUMBER(FIND('1 - General description'!$H$54,F20)),ISNUMBER(FIND('1 - General description'!$H$55,F20)),ISNUMBER(FIND('1 - General description'!$H$56,F20)),ISNUMBER(FIND('1 - General description'!$H$57,F20)),ISNUMBER(FIND('1 - General description'!$H$58,F20)),ISNUMBER(FIND('1 - General description'!$H$59,F20)),ISNUMBER(FIND('1 - General description'!$H$60,F20)),ISNUMBER(FIND('1 - General description'!$H$61,F20)),ISNUMBER(FIND('1 - General description'!$H$62,F20)),ISNUMBER(FIND('1 - General description'!$H$63,F20)),ISNUMBER(FIND('1 - General description'!$H$64,F20))) -> TRUE
A21: 4 | B21: Identity and access management / Gestion des identités et des accès | C21: 4.3 | D21: Staff identification / Identification du personnel | E21: A list of the client’s members of staff authorised to request services from the service provider shall be drawn up together with a means of authenticating those persons. This rule shall also apply to the service provider’s members of staff who need to contact the client’s members of staff – for example, for validation purposes or regarding operations that the service provider needs to carry out. The service provider shall create and regularly update a list of members of staff authorised to access the client’s data and/or to interact with the client’s resources, together with their level of authorisation (access types and client’s resources concerned). This list shall be made available to the client. / La liste des personnels du client autorisés à solliciter des services auprès du prestataire est définie ainsi qu'un moyen d'authentification de ces personnels. Cette règle s'applique réciproquement pour les personnels du prestataire qui doivent solliciter des personnels du client, par exemple à des fins de validation pour des opérations que doit mener le prestataire. Le prestataire élabore et met à jour régulièrement une liste des personnels autorisés à accéder aux données du client et/ou à intervenir sur les ressources du client ainsi que leur niveau d’habilitation (types d’accès et ressources concernées du client). Cette liste est tenue à la disposition du client. | F21: A, B, C, D, E, F, G, H, I, J, K, L, M | G21: =IF(AND('1 - General description'!$G$51=FALSE, K21= TRUE),"Applicable","N.A") -> Applicable | K21: =OR(ISNUMBER(FIND('1 - General description'!$H$51,F21)),ISNUMBER(FIND('1 - General description'!$H$52,F21)),ISNUMBER(FIND('1 - General description'!$H$53,F21)),ISNUMBER(FIND('1 - General description'!$H$54,F21)),ISNUMBER(FIND('1 - General description'!$H$55,F21)),ISNUMBER(FIND('1 - General description'!$H$56,F21)),ISNUMBER(FIND('1 - General description'!$H$57,F21)),ISNUMBER(FIND('1 - General description'!$H$58,F21)),ISNUMBER(FIND('1 - General description'!$H$59,F21)),ISNUMBER(FIND('1 - General description'!$H$60,F21)),ISNUMBER(FIND('1 - General description'!$H$61,F21)),ISNUMBER(FIND('1 - General description'!$H$62,F21)),ISNUMBER(FIND('1 - General description'!$H$63,F21)),ISNUMBER(FIND('1 - General description'!$H$64,F21))) -> TRUE
A22: 4 | B22: Identity and access management / Gestion des identités et des accès | C22: 4.4 | D22: Segregation of duties / Ségrégation des tâches | E22: The service provider shall implement strict management of the separation of duties when allocating access rights to its staff. / Le prestataire met en œuvre une gestion rigoureuse de la ségrégation des tâches dans l'attribution des droits d'accès pour ses personnels. | F22: D, E, F, H | G22: =IF(AND('1 - General description'!$G$51=FALSE, K22= TRUE),"Applicable","N.A") -> Applicable | K22: =OR(ISNUMBER(FIND('1 - General description'!$H$51,F22)),ISNUMBER(FIND('1 - General description'!$H$52,F22)),ISNUMBER(FIND('1 - General description'!$H$53,F22)),ISNUMBER(FIND('1 - General description'!$H$54,F22)),ISNUMBER(FIND('1 - General description'!$H$55,F22)),ISNUMBER(FIND('1 - General description'!$H$56,F22)),ISNUMBER(FIND('1 - General description'!$H$57,F22)),ISNUMBER(FIND('1 - General description'!$H$58,F22)),ISNUMBER(FIND('1 - General description'!$H$59,F22)),ISNUMBER(FIND('1 - General description'!$H$60,F22)),ISNUMBER(FIND('1 - General description'!$H$61,F22)),ISNUMBER(FIND('1 - General description'!$H$62,F22)),ISNUMBER(FIND('1 - General description'!$H$63,F22)),ISNUMBER(FIND('1 - General description'!$H$64,F22))) -> TRUE
A23: 4 | B23: Identity and access management / Gestion des identités et des accès | C23: 4.5 | D23: Password management / Gestion des mots de passe | E23: The service provider’s staff shall use strong passwords: minimum 12 characters for standard accounts and minimum 16 characters for privileged accounts. Passwords shall be changed at least every ninety (90) days. Passwords must be complex and contain at least letters, numbers and special characters. The service provider’s members of staff undertake never to ask the client’s employees for their password when carrying out their work. If a user’s password is required in order to carry out a particular operation, the service provider’s staff must ask the user concerned to enter their password personally. The service provider undertakes to ensure that the accounts and passwords used by its staff concerning specificly the client’s resources are specific to the client, and thus different from the accounts and passwords used for its other clients. Every equipment subject to remote monitoring or remote maintenance must have an account which is reserved for that purpose and for which the identification and authentication parameters are different from those of all other equipment. / Les personnels du prestataire utilisent des mots de passe robustes : 12 caractères a minima pour des comptes standard, 16 caractères minima pour des comptes à privilèges. L’âge de ces mots de passe n'excéde pas 90 jours. Ces mots de passe sont complexes et comportent a minima des lettres, chiffres et caractères spéciaux. Les personnels du prestataire s’engagent à ne jamais demander leur mot de passe à des personnels du client, dans le cadre de leurs interventions. Par exemple, si la saisie d’un mot de passe d’un utilisateur est nécessaire pour mener à bien une intervention, les personnels du prestataire peuvent demander à l’utilisateur concerné de saisir lui-même son mot de passe. Le prestataire s’engage à ce que les comptes et mots de passe utilisés par ses personnels et concernant spécifiquement le système d'information du client soient dédiés au client, donc différents des comptes et mots de passe utilisés pour ses autres clients. Chaque équipement objet d’une télésurveillance ou d’une télémaintenance doit disposer d’un compte réservé à cette fin et dont les paramètres d’identification et d’authentification sont différents de ceux de tout autre équipement. | F23: A, B, C, D, E, F, M, Z | G23: =IF(K23= TRUE,"Applicable","N.A") -> Applicable | K23: =OR(ISNUMBER(FIND('1 - General description'!$H$51,F23)),ISNUMBER(FIND('1 - General description'!$H$52,F23)),ISNUMBER(FIND('1 - General description'!$H$53,F23)),ISNUMBER(FIND('1 - General description'!$H$54,F23)),ISNUMBER(FIND('1 - General description'!$H$55,F23)),ISNUMBER(FIND('1 - General description'!$H$56,F23)),ISNUMBER(FIND('1 - General description'!$H$57,F23)),ISNUMBER(FIND('1 - General description'!$H$58,F23)),ISNUMBER(FIND('1 - General description'!$H$59,F23)),ISNUMBER(FIND('1 - General description'!$H$60,F23)),ISNUMBER(FIND('1 - General description'!$H$61,F23)),ISNUMBER(FIND('1 - General description'!$H$62,F23)),ISNUMBER(FIND('1 - General description'!$H$63,F23)),ISNUMBER(FIND('1 - General description'!$H$64,F23))) -> TRUE
A24: 4 | B24: Identity and access management / Gestion des identités et des accès | C24: 4.6 | D24: Single Sign-On Authentication / Authentification Single Sign-On | E24: Single Sign-On (SSO) authentication must be configured with the Sephora (or LVMH group’s) SSO instance, based on the Okta solution. All solutions provided as part of the service, on which Sephora users authenticate via a Sephora email address, must therefore be compatible with Okta, SAML or OpenID Connect protocols. / L’authentification Single Sign-On (SSO) doit être configurée avec l’instance SSO de Sephora (ou du groupe LVMH), basée sur la solution Okta. Toutes les solutions fournies dans le cadre du service, sur lesquelles des utilisateurs Sephora s’authentifient via une adresse email Sephora, doivent donc être compatibles avec les protocoles Okta, SAML ou OpenID Connect. | F24: E, F, G | G24: =IF(AND('1 - General description'!$G$51=FALSE, K24= TRUE),"Applicable","N.A") -> Applicable | K24: =OR(ISNUMBER(FIND('1 - General description'!$H$51,F24)),ISNUMBER(FIND('1 - General description'!$H$52,F24)),ISNUMBER(FIND('1 - General description'!$H$53,F24)),ISNUMBER(FIND('1 - General description'!$H$54,F24)),ISNUMBER(FIND('1 - General description'!$H$55,F24)),ISNUMBER(FIND('1 - General description'!$H$56,F24)),ISNUMBER(FIND('1 - General description'!$H$57,F24)),ISNUMBER(FIND('1 - General description'!$H$58,F24)),ISNUMBER(FIND('1 - General description'!$H$59,F24)),ISNUMBER(FIND('1 - General description'!$H$60,F24)),ISNUMBER(FIND('1 - General description'!$H$61,F24)),ISNUMBER(FIND('1 - General description'!$H$62,F24)),ISNUMBER(FIND('1 - General description'!$H$63,F24)),ISNUMBER(FIND('1 - General description'!$H$64,F24))) -> TRUE
A25: 4 | B25: Identity and access management / Gestion des identités et des accès | C25: 4.7 | D25: Default accounts and passwords / Comptes et mots de passe par défaut | E25: All default privileged accounts amust be disabled, deleted or renamed. A least, default passwords associated with these accounts must be replaced by strong passords meeting rule 5.8. Storage of these passwords must be secure (ex: electronic safe solution). / Tous les comptes à privilèges par défaut doivent être supprimés, désactivés ou renommés. A minima les mots de passe par défaut associés à ces comptes doivent être remplacés par des mots de passe conformes à la règle "Gestion des mots de passe". Le stockage de ces mots de passe doit être fait de façon sécurisée (par exemple : coffre-fort logiciel à mots de passe). | F25: B, C, D, E, F, M | G25: =IF(AND('1 - General description'!$G$51=FALSE, K25= TRUE),"Applicable","N.A") -> Applicable | K25: =OR(ISNUMBER(FIND('1 - General description'!$H$51,F25)),ISNUMBER(FIND('1 - General description'!$H$52,F25)),ISNUMBER(FIND('1 - General description'!$H$53,F25)),ISNUMBER(FIND('1 - General description'!$H$54,F25)),ISNUMBER(FIND('1 - General description'!$H$55,F25)),ISNUMBER(FIND('1 - General description'!$H$56,F25)),ISNUMBER(FIND('1 - General description'!$H$57,F25)),ISNUMBER(FIND('1 - General description'!$H$58,F25)),ISNUMBER(FIND('1 - General description'!$H$59,F25)),ISNUMBER(FIND('1 - General description'!$H$60,F25)),ISNUMBER(FIND('1 - General description'!$H$61,F25)),ISNUMBER(FIND('1 - General description'!$H$62,F25)),ISNUMBER(FIND('1 - General description'!$H$63,F25)),ISNUMBER(FIND('1 - General description'!$H$64,F25))) -> TRUE
